Workbook

Sheet A.S.PRINTOUT
A1: Last Scraped Date | B1: 04.03.26 | C1: BRENTWOOD PARK - BURNABY NORTH
A2: COPY | B2: Address | C2: SOLD | D2: List | E2: x - S.Date | F2: DOM | G2: List# | H2: Build | I2: Lot Size | J2: Bed | K2: Bath | L2: Sqft | M2: Kitch | N2: Land | O2: Total ASS | P2: S vs ASS
B3: SOLDS
A4: =IF(B4="","-",IF(COUNTIF(E.DETACHED!B:B,B4)+COUNTIF('A.S.PRINTOUT'!B:B,B4)>1,COUNTIF(E.DETACHED!B:B,B4)+COUNTIF('A.S.PRINTOUT'!B:B,B4)-1,"-"))
A5: =IF(B5="","-",IF(COUNTIF(E.DETACHED!B:B,B5)+COUNTIF('A.S.PRINTOUT'!B:B,B5)>1,COUNTIF(E.DETACHED!B:B,B5)+COUNTIF('A.S.PRINTOUT'!B:B,B5)-1,"-")) | B5: 4581 UNION STREET | C5: 1628000 | D5: 1799900 | E5: 46063 | F5: 14 | G5: 1 | H5: 1979 | I5: 4026 | J5: 4 | K5: 3 | L5: 2655 | M5: 2 | N5: 1558000 | O5: 1708000 | P5: =C5-O5
A6: =IF(B6="","-",IF(COUNTIF(E.DETACHED!B:B,B6)+COUNTIF('A.S.PRINTOUT'!B:B,B6)>1,COUNTIF(E.DETACHED!B:B,B6)+COUNTIF('A.S.PRINTOUT'!B:B,B6)-1,"-")) | B6: 4930 VENABLES STREET | C6: 2200000 | D6: 2499000 | E6: 46054 | F6: 76 | G6: 2 | H6: 1991 | I6: 7320 | J6: 8 | K6: 6 | L6: 4383 | M6: 2 | N6: 2072000 | O6: 2553000 | P6: =C6-O6
A7: =IF(B7="","-",IF(COUNTIF(E.DETACHED!B:B,B7)+COUNTIF('A.S.PRINTOUT'!B:B,B7)>1,COUNTIF(E.DETACHED!B:B,B7)+COUNTIF('A.S.PRINTOUT'!B:B,B7)-1,"-")) | B7: 5031 HALIFAX STREET | C7: 1750000 | D7: 1799000 | E7: 46000 | F7: 8 | G7: 2 | H7: 1986 | I7: 6002 | J7: 6 | K7: 3 | L7: 2951 | M7: 2 | N7: 1847000 | O7: 2102000 | P7: =C7-O7
A8: =IF(B8="","-",IF(COUNTIF(E.DETACHED!B:B,B8)+COUNTIF('A.S.PRINTOUT'!B:B,B8)>1,COUNTIF(E.DETACHED!B:B,B8)+COUNTIF('A.S.PRINTOUT'!B:B,B8)-1,"-")) | B8: 5060 VENABLES STREET | C8: 1844000 | D8: 1868000 | E8: 45913 | F8: 26 | G8: 1 | H8: 1960 | I8: 8052 | J8: 5 | K8: 2 | L8: 2149 | M8: 1 | N8: 2141000 | O8: 2190500 | P8: =C8-O8
A9: =IF(B9="","-",IF(COUNTIF(E.DETACHED!B:B,B9)+COUNTIF('A.S.PRINTOUT'!B:B,B9)>1,COUNTIF(E.DETACHED!B:B,B9)+COUNTIF('A.S.PRINTOUT'!B:B,B9)-1,"-")) | B9: 4623 NAPIER STREET | C9: 2575000 | D9: 2599000 | E9: 45822 | F9: 11 | G9: 4 | H9: 1953 | I9: 6100 | J9: 5 | K9: 4 | L9: 2837 | M9: 2 | N9: 1866000 | O9: 2303000 | P9: =C9-O9
A10: =IF(B10="","-",IF(COUNTIF(E.DETACHED!B:B,B10)+COUNTIF('A.S.PRINTOUT'!B:B,B10)>1,COUNTIF(E.DETACHED!B:B,B10)+COUNTIF('A.S.PRINTOUT'!B:B,B10)-1,"-")) | B10: 4819 FAIRLAWN DRIVE | C10: 2180000 | D10: 2299000 | E10: 45788 | F10: 6 | G10: 1 | H10: 1957 | I10: 7320 | J10: 4 | K10: 2 | L10: 3550 | M10: 1 | N10: 1996000 | O10: 2070800 | P10: =C10-O10
A11: =IF(B11="","-",IF(COUNTIF(E.DETACHED!B:B,B11)+COUNTIF('A.S.PRINTOUT'!B:B,B11)>1,COUNTIF(E.DETACHED!B:B,B11)+COUNTIF('A.S.PRINTOUT'!B:B,B11)-1,"-")) | B11: 4720 SOUTHLAWN DRIVE | C11: 2140000 | D11: 2320000 | E11: 45755 | F11: 7 | G11: 1 | H11: 1954 | I11: 6307 | J11: 4 | K11: 2 | L11: 2278 | M11: 2 | N11: 1990000 | O11: 2044100 | P11: =C11-O11
A12: =IF(B12="","-",IF(COUNTIF(E.DETACHED!B:B,B12)+COUNTIF('A.S.PRINTOUT'!B:B,B12)>1,COUNTIF(E.DETACHED!B:B,B12)+COUNTIF('A.S.PRINTOUT'!B:B,B12)-1,"-")) | B12: 4780 BRENTLAWN DRIVE | C12: 2090000 | D12: 2150000 | E12: 45705 | F12: 19 | G12: 1 | H12: 1953 | I12: 6588 | J12: 4 | K12: 2 | L12: 1970 | M12: 1 | N12: 1927000 | O12: 1976100 | P12: =C12-O12
A13: =IF(B13="","-",IF(COUNTIF(E.DETACHED!B:B,B13)+COUNTIF('A.S.PRINTOUT'!B:B,B13)>1,COUNTIF(E.DETACHED!B:B,B13)+COUNTIF('A.S.PRINTOUT'!B:B,B13)-1,"-")) | B13: 4624 ALPHA DRIVE | C13: 2100000 | D13: 1998000 | E13: 45684 | F13: 7 | G13: 1 | H13: 1956 | I13: 6348 | J13: 4 | K13: 2 | L13: 2526 | M13: 2 | N13: 1900000 | O13: 1952100 | P13: =C13-O13
A14: =IF(B14="","-",IF(COUNTIF(E.DETACHED!B:B,B14)+COUNTIF('A.S.PRINTOUT'!B:B,B14)>1,COUNTIF(E.DETACHED!B:B,B14)+COUNTIF('A.S.PRINTOUT'!B:B,B14)-1,"-")) | B14: 4260 GRAVELEY STREET | C14: 1480000 | D14: 1499900 | E14: 45678 | F14: 41 | G14: 2 | H14: 1987 | I14: 4136 | J14: 3 | K14: 3 | L14: 2356 | M14: 1 | N14: 1409000 | O14: 1679000 | P14: =C14-O14
B15: {=SUMPRODUCT(--(LEN(TRIM(B7:B14))>0))}
A16: =IF(B15="","-",IF(COUNTIF(E.DETACHED!B:B,B15)+COUNTIF('A.S.PRINTOUT'!B:B,B15)>1,COUNTIF(E.DETACHED!B:B,B15)+COUNTIF('A.S.PRINTOUT'!B:B,B15)-1,"-"))
A17: =IF(B17="","-",IF(COUNTIF(E.DETACHED!B:B,B17)+COUNTIF('A.S.PRINTOUT'!B:B,B17)>1,COUNTIF(E.DETACHED!B:B,B17)+COUNTIF('A.S.PRINTOUT'!B:B,B17)-1,"-")) | B17: 4823 WESTLAWN DRIVE | C17: 2018000 | D17: 2150000 | E17: 45644 | F17: 17 | G17: 2 | H17: 1956 | I17: 6344 | J17: 5 | K17: 2 | L17: 2059 | M17: 1 | N17: 1907000 | O17: 1989900 | P17: =C17-O17
A18: =IF(B18="","-",IF(COUNTIF(E.DETACHED!B:B,B18)+COUNTIF('A.S.PRINTOUT'!B:B,B18)>1,COUNTIF(E.DETACHED!B:B,B18)+COUNTIF('A.S.PRINTOUT'!B:B,B18)-1,"-")) | B18: 4702 PARKER STREET | C18: 2040000 | D18: 2150000 | E18: 45635 | F18: 77 | G18: 2 | H18: 1959 | I18: 7076 | J18: 7 | K18: 5 | L18: 3272 | M18: 2 | N18: 1810000 | O18: 1946000 | P18: =C18-O18
A19: =IF(B19="","-",IF(COUNTIF(E.DETACHED!B:B,B19)+COUNTIF('A.S.PRINTOUT'!B:B,B19)>1,COUNTIF(E.DETACHED!B:B,B19)+COUNTIF('A.S.PRINTOUT'!B:B,B19)-1,"-")) | B19: 4547 MIDLAWN DRIVE | C19: 2125000 | D19: 1999900 | E19: 45622 | F19: 12 | G19: 1 | H19: 1955 | I19: 6344 | J19: 3 | K19: 2 | L19: 2412 | M19: 1 | N19: 1894000 | O19: 1945700 | P19: =C19-O19
A20: =IF(B20="","-",IF(COUNTIF(E.DETACHED!B:B,B20)+COUNTIF('A.S.PRINTOUT'!B:B,B20)>1,COUNTIF(E.DETACHED!B:B,B20)+COUNTIF('A.S.PRINTOUT'!B:B,B20)-1,"-")) | B20: 1387 SPRINGER AVENUE | C20: 2420000 | D20: 2499900 | E20: 45607 | F20: 7 | G20: 1 | H20: 1989 | I20: 7866 | J20: 6 | K20: 5 | L20: 4737 | M20: 2 | N20: 1782000 | O20: 2386000 | P20: =C20-O20
A21: =IF(B21="","-",IF(COUNTIF(E.DETACHED!B:B,B21)+COUNTIF('A.S.PRINTOUT'!B:B,B21)>1,COUNTIF(E.DETACHED!B:B,B21)+COUNTIF('A.S.PRINTOUT'!B:B,B21)-1,"-")) | B21: 4830 WESTLAWN DRIVE | C21: 2000000 | D21: 1998000 | E21: 45600 | F21: 7 | G21: 1 | H21: 1958 | I21: 6710 | J21: 3 | K21: 2 | L21: 2544 | M21: 1 | N21: 1937000 | O21: 1990700 | P21: =C21-O21
A22: =IF(B22="","-",IF(COUNTIF(E.DETACHED!B:B,B22)+COUNTIF('A.S.PRINTOUT'!B:B,B22)>1,COUNTIF(E.DETACHED!B:B,B22)+COUNTIF('A.S.PRINTOUT'!B:B,B22)-1,"-")) | B22: 1695 TARALAWN COURT | C22: 2147500 | D22: 2250000 | E22: 45565 | F22: 13 | G22: 1 | H22: 1966 | I22: 7020 | J22: 5 | K22: 3 | L22: 2701 | M22: 1 | N22: 1946000 | O22: 2040800 | P22: =C22-O22
A23: =IF(B23="","-",IF(COUNTIF(E.DETACHED!B:B,B23)+COUNTIF('A.S.PRINTOUT'!B:B,B23)>1,COUNTIF(E.DETACHED!B:B,B23)+COUNTIF('A.S.PRINTOUT'!B:B,B23)-1,"-")) | B23: 4841 RIDGELAWN DRIVE | C23: 2086000 | D23: 2099900 | E23: 45558 | F23: 48 | G23: 2 | H23: 1955 | I23: 6655 | J23: 4 | K23: 2 | L23: 2489 | M23: 1 | N23: 2025000 | O23: 2080400 | P23: =C23-O23
A24: =IF(B24="","-",IF(COUNTIF(E.DETACHED!B:B,B24)+COUNTIF('A.S.PRINTOUT'!B:B,B24)>1,COUNTIF(E.DETACHED!B:B,B24)+COUNTIF('A.S.PRINTOUT'!B:B,B24)-1,"-"))
A25: =IF(B25="","-",IF(COUNTIF(E.DETACHED!B:B,B25)+COUNTIF('A.S.PRINTOUT'!B:B,B25)>1,COUNTIF(E.DETACHED!B:B,B25)+COUNTIF('A.S.PRINTOUT'!B:B,B25)-1,"-"))
A26: =IF(B26="","-",IF(COUNTIF(E.DETACHED!B:B,B26)+COUNTIF('A.S.PRINTOUT'!B:B,B26)>1,COUNTIF(E.DETACHED!B:B,B26)+COUNTIF('A.S.PRINTOUT'!B:B,B26)-1,"-")) | B26: x - Address | C26: Expiry | D26: List | E26: L.Date | F26: DOM | G26: List# | H26: Build | I26: Lot Size | J26: Bed | K26: Bath | L26: Sqft | M26: Kitch | N26: Land | O26: Total ASS | P26: D.EXP
A27: =IF(B27="","-",IF(COUNTIF(E.DETACHED!B:B,B27)+COUNTIF('A.S.PRINTOUT'!B:B,B27)>1,COUNTIF(E.DETACHED!B:B,B27)+COUNTIF('A.S.PRINTOUT'!B:B,B27)-1,"-")) | B27: CURRENT ACTIVES
A28: =IF(B28="","-",IF(COUNTIF(E.DETACHED!B:B,B28)+COUNTIF('A.S.PRINTOUT'!B:B,B28)>1,COUNTIF(E.DETACHED!B:B,B28)+COUNTIF('A.S.PRINTOUT'!B:B,B28)-1,"-"))
A29: =IF(B29="","-",IF(COUNTIF(E.DETACHED!B:B,B29)+COUNTIF('A.S.PRINTOUT'!B:B,B29)>1,COUNTIF(E.DETACHED!B:B,B29)+COUNTIF('A.S.PRINTOUT'!B:B,B29)-1,"-")) | B29: 4645 BRENTLAWN DRIVE | C29: 3/31/2026 | D29: 4000000 | E29: 3/20/2025 | F29: =IF(E29="","",MAX(0, TODAY() - IF(ISNUMBER(E29), E29, IFERROR( DATEVALUE(SUBSTITUTE(E29,CHAR(160)," ")), DATE(VALUE(RIGHT(E29,4)), VALUE(LEFT(E29,FIND("/",E29)-1)), VALUE(MID(E29,FIND("/",E29)+1, FIND("/",E29, FIND("/",E29)+1)-FIND("/",E29)-1)) ) ) ) )) | G29: 1 | H29: 1954 | I29: 6466 | J29: 4 | K29: 4 | L29: 2024 | M29: 3 | N29: 1816000 | O29: 1931000 | P29: =IF(C29="","", IF(ISNUMBER(C29), _xlfn.LET(_xlpm.days, C29 - TODAY(), IF(_xlpm.days<0, "Expired", _xlpm.days)), _xlfn.LET( _xlpm.txt, C29, _xlpm.y, RIGHT(_xlpm.txt,4)*1, _xlpm.m, LEFT(_xlpm.txt, FIND("/",_xlpm.txt)-1)*1, _xlpm.d, MID(_xlpm.txt, FIND("/",_xlpm.txt)+1, FIND("/",_xlpm.txt, FIND("/",_xlpm.txt)+1) - FIND("/",_xlpm.txt) -1 )*1, _xlpm.days, DATE(_xlpm.y,_xlpm.m,_xlpm.d) - TODAY(), IF(_xlpm.days<0, "Expired", _xlpm.days) ) ) )
A30: =IF(B30="","-",IF(COUNTIF(E.DETACHED!B:B,B30)+COUNTIF('A.S.PRINTOUT'!B:B,B30)>1,COUNTIF(E.DETACHED!B:B,B30)+COUNTIF('A.S.PRINTOUT'!B:B,B30)-1,"-")) | B30: 1250 DELTA AVENUE | C30: 46229 | D30: 1795000 | E30: 46048 | F30: =IF(E30="","",MAX(0, TODAY() - IF(ISNUMBER(E30), E30, IFERROR( DATEVALUE(SUBSTITUTE(E30,CHAR(160)," ")), DATE(VALUE(RIGHT(E30,4)), VALUE(LEFT(E30,FIND("/",E30)-1)), VALUE(MID(E30,FIND("/",E30)+1, FIND("/",E30, FIND("/",E30)+1)-FIND("/",E30)-1)) ) ) ) )) | G30: 1 | H30: 1966 | I30: 7200 | J30: 4 | K30: 3 | L30: 2754 | M30: 1 | N30: 1767000 | O30: 1831400 | P30: =IF(C30="","", IF(ISNUMBER(C30), _xlfn.LET(_xlpm.days, C30 - TODAY(), IF(_xlpm.days<0, "Expired", _xlpm.days)), _xlfn.LET( _xlpm.txt, C30, _xlpm.y, RIGHT(_xlpm.txt,4)*1, _xlpm.m, LEFT(_xlpm.txt, FIND("/",_xlpm.txt)-1)*1, _xlpm.d, MID(_xlpm.txt, FIND("/",_xlpm.txt)+1, FIND("/",_xlpm.txt, FIND("/",_xlpm.txt)+1) - FIND("/",_xlpm.txt) -1 )*1, _xlpm.days, DATE(_xlpm.y,_xlpm.m,_xlpm.d) - TODAY(), IF(_xlpm.days<0, "Expired", _xlpm.days) ) ) )
A31: =IF(B31="","-",IF(COUNTIF(E.DETACHED!B:B,B31)+COUNTIF('A.S.PRINTOUT'!B:B,B31)>1,COUNTIF(E.DETACHED!B:B,B31)+COUNTIF('A.S.PRINTOUT'!B:B,B31)-1,"-")) | P31: =IF(C31="","", IF(ISNUMBER(C31), _xlfn.LET(_xlpm.days, C31 - TODAY(), IF(_xlpm.days<0, "Expired", _xlpm.days)), _xlfn.LET( _xlpm.txt, C31, _xlpm.y, RIGHT(_xlpm.txt,4)*1, _xlpm.m, LEFT(_xlpm.txt, FIND("/",_xlpm.txt)-1)*1, _xlpm.d, MID(_xlpm.txt, FIND("/",_xlpm.txt)+1, FIND("/",_xlpm.txt, FIND("/",_xlpm.txt)+1) - FIND("/",_xlpm.txt) -1 )*1, _xlpm.days, DATE(_xlpm.y,_xlpm.m,_xlpm.d) - TODAY(), IF(_xlpm.days<0, "Expired", _xlpm.days) ) ) )
A32: =IF(B32="","-",IF(COUNTIF(E.DETACHED!B:B,B32)+COUNTIF('A.S.PRINTOUT'!B:B,B32)>1,COUNTIF(E.DETACHED!B:B,B32)+COUNTIF('A.S.PRINTOUT'!B:B,B32)-1,"-")) | B32: 4810 FAIRLAWN DRIVE | C32: 46203 | D32: 2049000 | E32: 46027 | F32: =IF(E32="","",MAX(0, TODAY() - IF(ISNUMBER(E32), E32, IFERROR( DATEVALUE(SUBSTITUTE(E32,CHAR(160)," ")), DATE(VALUE(RIGHT(E32,4)), VALUE(LEFT(E32,FIND("/",E32)-1)), VALUE(MID(E32,FIND("/",E32)+1, FIND("/",E32, FIND("/",E32)+1)-FIND("/",E32)-1)) ) ) ) )) | G32: 1 | H32: 1956 | I32: 7320 | J32: 6 | K32: 2 | L32: 2582 | M32: 2 | N32: 1995000 | O32: 2049900 | P32: =IF(C32="","", IF(ISNUMBER(C32), _xlfn.LET(_xlpm.days, C32 - TODAY(), IF(_xlpm.days<0, "Expired", _xlpm.days)), _xlfn.LET( _xlpm.txt, C32, _xlpm.y, RIGHT(_xlpm.txt,4)*1, _xlpm.m, LEFT(_xlpm.txt, FIND("/",_xlpm.txt)-1)*1, _xlpm.d, MID(_xlpm.txt, FIND("/",_xlpm.txt)+1, FIND("/",_xlpm.txt, FIND("/",_xlpm.txt)+1) - FIND("/",_xlpm.txt) -1 )*1, _xlpm.days, DATE(_xlpm.y,_xlpm.m,_xlpm.d) - TODAY(), IF(_xlpm.days<0, "Expired", _xlpm.days) ) ) )
B33: 4824 FAIRLAWN DRIVE | C33: 46386 | D33: 2228000 | E33: 46100 | F33: =IF(E33="","",MAX(0, TODAY() - IF(ISNUMBER(E33), E33, IFERROR( DATEVALUE(SUBSTITUTE(E33,CHAR(160)," ")), DATE(VALUE(RIGHT(E33,4)), VALUE(LEFT(E33,FIND("/",E33)-1)), VALUE(MID(E33,FIND("/",E33)+1, FIND("/",E33, FIND("/",E33)+1)-FIND("/",E33)-1)) ) ) ) )) | G33: 1 | H33: 1956 | I33: 7320 | J33: 6 | K33: 3 | L33: 2715 | M33: 3 | N33: 1996000 | O33: 2172000 | P33: =IF(C33="","", IF(ISNUMBER(C33), _xlfn.LET(_xlpm.days, C33 - TODAY(), IF(_xlpm.days<0, "Expired", _xlpm.days)), _xlfn.LET( _xlpm.txt, C33, _xlpm.y, RIGHT(_xlpm.txt,4)*1, _xlpm.m, LEFT(_xlpm.txt, FIND("/",_xlpm.txt)-1)*1, _xlpm.d, MID(_xlpm.txt, FIND("/",_xlpm.txt)+1, FIND("/",_xlpm.txt, FIND("/",_xlpm.txt)+1) - FIND("/",_xlpm.txt) -1 )*1, _xlpm.days, DATE(_xlpm.y,_xlpm.m,_xlpm.d) - TODAY(), IF(_xlpm.days<0, "Expired", _xlpm.days) ) ) )
A35: =IF(B35="","-",IF(COUNTIF(E.DETACHED!B:B,B35)+COUNTIF('A.S.PRINTOUT'!B:B,B35)>1,COUNTIF(E.DETACHED!B:B,B35)+COUNTIF('A.S.PRINTOUT'!B:B,B35)-1,"-")) | B35: 4468 GRAVELEY STREET | C35: 46229 | D35: 1875000 | E35: 46048 | F35: =IF(E35="","",MAX(0, TODAY() - IF(ISNUMBER(E35), E35, IFERROR( DATEVALUE(SUBSTITUTE(E35,CHAR(160)," ")), DATE(VALUE(RIGHT(E35,4)), VALUE(LEFT(E35,FIND("/",E35)-1)), VALUE(MID(E35,FIND("/",E35)+1, FIND("/",E35, FIND("/",E35)+1)-FIND("/",E35)-1)) ) ) ) )) | G35: 1 | H35: 1991 | I35: 3748 | J35: 4 | K35: 3 | L35: 2325 | M35: 2 | N35: 1316000 | O35: 1592000 | P35: =IF(C35="","", IF(ISNUMBER(C35), _xlfn.LET(_xlpm.days, C35 - TODAY(), IF(_xlpm.days<0, "Expired", _xlpm.days)), _xlfn.LET( _xlpm.txt, C35, _xlpm.y, RIGHT(_xlpm.txt,4)*1, _xlpm.m, LEFT(_xlpm.txt, FIND("/",_xlpm.txt)-1)*1, _xlpm.d, MID(_xlpm.txt, FIND("/",_xlpm.txt)+1, FIND("/",_xlpm.txt, FIND("/",_xlpm.txt)+1) - FIND("/",_xlpm.txt) -1 )*1, _xlpm.days, DATE(_xlpm.y,_xlpm.m,_xlpm.d) - TODAY(), IF(_xlpm.days<0, "Expired", _xlpm.days) ) ) )
A36: =IF(B36="","-",IF(COUNTIF(E.DETACHED!B:B,B36)+COUNTIF('A.S.PRINTOUT'!B:B,B36)>1,COUNTIF(E.DETACHED!B:B,B36)+COUNTIF('A.S.PRINTOUT'!B:B,B36)-1,"-")) | B36: 4871 HIGHLAWN DRIVE | C36: 46234 | D36: 2280000 | E36: 46045 | F36: =IF(E36="","",MAX(0, TODAY() - IF(ISNUMBER(E36), E36, IFERROR( DATEVALUE(SUBSTITUTE(E36,CHAR(160)," ")), DATE(VALUE(RIGHT(E36,4)), VALUE(LEFT(E36,FIND("/",E36)-1)), VALUE(MID(E36,FIND("/",E36)+1, FIND("/",E36, FIND("/",E36)+1)-FIND("/",E36)-1)) ) ) ) )) | G36: 3 | H36: 1954 | I36: 2375 | J36: 6 | K36: 4 | L36: 2375 | M36: 2 | N36: 2120000 | O36: 2222000 | P36: =IF(C36="","", IF(ISNUMBER(C36), _xlfn.LET(_xlpm.days, C36 - TODAY(), IF(_xlpm.days<0, "Expired", _xlpm.days)), _xlfn.LET( _xlpm.txt, C36, _xlpm.y, RIGHT(_xlpm.txt,4)*1, _xlpm.m, LEFT(_xlpm.txt, FIND("/",_xlpm.txt)-1)*1, _xlpm.d, MID(_xlpm.txt, FIND("/",_xlpm.txt)+1, FIND("/",_xlpm.txt, FIND("/",_xlpm.txt)+1) - FIND("/",_xlpm.txt) -1 )*1, _xlpm.days, DATE(_xlpm.y,_xlpm.m,_xlpm.d) - TODAY(), IF(_xlpm.days<0, "Expired", _xlpm.days) ) ) ) | R36: R3041486, | S36: YANYING ZHOU | MEI PAN | T36: #2102 - 7063 HALL AVENUE | U36: BURNABY, BC V5E 0A5 | V36: T
A37: =IF(B37="","-",IF(COUNTIF(E.DETACHED!B:B,B37)+COUNTIF('A.S.PRINTOUT'!B:B,B37)>1,COUNTIF(E.DETACHED!B:B,B37)+COUNTIF('A.S.PRINTOUT'!B:B,B37)-1,"-")) | B37: 4881 SOUTHLAWN DRIVE | C37: 46356 | D37: 2280000 | E37: 46056 | F37: =IF(E37="","",MAX(0, TODAY() - IF(ISNUMBER(E37), E37, IFERROR( DATEVALUE(SUBSTITUTE(E37,CHAR(160)," ")), DATE(VALUE(RIGHT(E37,4)), VALUE(LEFT(E37,FIND("/",E37)-1)), VALUE(MID(E37,FIND("/",E37)+1, FIND("/",E37, FIND("/",E37)+1)-FIND("/",E37)-1)) ) ) ) )) | G37: 1 | H37: 1995 | I37: 7564 | J37: 7 | K37: 6 | L37: 4020 | M37: 3 | N37: 1817000 | O37: 2440000 | P37: =IF(C37="","", IF(ISNUMBER(C37), _xlfn.LET(_xlpm.days, C37 - TODAY(), IF(_xlpm.days<0, "Expired", _xlpm.days)), _xlfn.LET( _xlpm.txt, C37, _xlpm.y, RIGHT(_xlpm.txt,4)*1, _xlpm.m, LEFT(_xlpm.txt, FIND("/",_xlpm.txt)-1)*1, _xlpm.d, MID(_xlpm.txt, FIND("/",_xlpm.txt)+1, FIND("/",_xlpm.txt, FIND("/",_xlpm.txt)+1) - FIND("/",_xlpm.txt) -1 )*1, _xlpm.days, DATE(_xlpm.y,_xlpm.m,_xlpm.d) - TODAY(), IF(_xlpm.days<0, "Expired", _xlpm.days) ) ) ) | R37: R2951736, | S37: ROBERT TING | HOUNG SENG TING | LIZA JEAN LAI-JANG | T37: 4881 SOUTHLAWN DRIVE | U37: BURNABY, BC V5C 3S7 | V37: O | W37: LA
A38: =IF(B38="","-",IF(COUNTIF(E.DETACHED!B:B,B38)+COUNTIF('A.S.PRINTOUT'!B:B,B38)>1,COUNTIF(E.DETACHED!B:B,B38)+COUNTIF('A.S.PRINTOUT'!B:B,B38)-1,"-")) | B38: 4516 PARKER STREET | C38: 5/30/2026 | D38: 2050000 | E38: 6/9/2025 | F38: =IF(E38="","",MAX(0, TODAY() - IF(ISNUMBER(E38), E38, IFERROR( DATEVALUE(SUBSTITUTE(E38,CHAR(160)," ")), DATE(VALUE(RIGHT(E38,4)), VALUE(LEFT(E38,FIND("/",E38)-1)), VALUE(MID(E38,FIND("/",E38)+1, FIND("/",E38, FIND("/",E38)+1)-FIND("/",E38)-1)) ) ) ) )) | G38: 1 | H38: 1949 | I38: 6222 | J38: 4 | K38: 0 | L38: 2184 | M38: 2 | N38: 1738000 | O38: 1859000 | P38: =IF(C38="","", IF(ISNUMBER(C38), _xlfn.LET(_xlpm.days, C38 - TODAY(), IF(_xlpm.days<0, "Expired", _xlpm.days)), _xlfn.LET( _xlpm.txt, C38, _xlpm.y, RIGHT(_xlpm.txt,4)*1, _xlpm.m, LEFT(_xlpm.txt, FIND("/",_xlpm.txt)-1)*1, _xlpm.d, MID(_xlpm.txt, FIND("/",_xlpm.txt)+1, FIND("/",_xlpm.txt, FIND("/",_xlpm.txt)+1) - FIND("/",_xlpm.txt) -1 )*1, _xlpm.days, DATE(_xlpm.y,_xlpm.m,_xlpm.d) - TODAY(), IF(_xlpm.days<0, "Expired", _xlpm.days) ) ) )
A39: =IF(B39="","-",IF(COUNTIF(E.DETACHED!B:B,B39)+COUNTIF('A.S.PRINTOUT'!B:B,B39)>1,COUNTIF(E.DETACHED!B:B,B39)+COUNTIF('A.S.PRINTOUT'!B:B,B39)-1,"-")) | B39: 4734 PARKER STREET | C39: 2/13/2026 | D39: 1988000 | E39: 8/13/2025 | F39: =IF(E39="","",MAX(0, TODAY() - IF(ISNUMBER(E39), E39, IFERROR( DATEVALUE(SUBSTITUTE(E39,CHAR(160)," ")), DATE(VALUE(RIGHT(E39,4)), VALUE(LEFT(E39,FIND("/",E39)-1)), VALUE(MID(E39,FIND("/",E39)+1, FIND("/",E39, FIND("/",E39)+1)-FIND("/",E39)-1)) ) ) ) )) | G39: 1 | H39: 1959 | I39: 6710 | J39: 6 | K39: 2 | L39: 3272 | M39: 2 | N39: 1780000 | O39: 1882000 | P39: =IF(C39="","", IF(ISNUMBER(C39), _xlfn.LET(_xlpm.days, C39 - TODAY(), IF(_xlpm.days<0, "Expired", _xlpm.days)), _xlfn.LET( _xlpm.txt, C39, _xlpm.y, RIGHT(_xlpm.txt,4)*1, _xlpm.m, LEFT(_xlpm.txt, FIND("/",_xlpm.txt)-1)*1, _xlpm.d, MID(_xlpm.txt, FIND("/",_xlpm.txt)+1, FIND("/",_xlpm.txt, FIND("/",_xlpm.txt)+1) - FIND("/",_xlpm.txt) -1 )*1, _xlpm.days, DATE(_xlpm.y,_xlpm.m,_xlpm.d) - TODAY(), IF(_xlpm.days<0, "Expired", _xlpm.days) ) ) )
A40: =IF(B40="","-",IF(COUNTIF(E.DETACHED!B:B,B40)+COUNTIF('A.S.PRINTOUT'!B:B,B40)>1,COUNTIF(E.DETACHED!B:B,B40)+COUNTIF('A.S.PRINTOUT'!B:B,B40)-1,"-")) | P40: =IF(C40="","", IF(ISNUMBER(C40), _xlfn.LET(_xlpm.days, C40 - TODAY(), IF(_xlpm.days<0, "Expired", _xlpm.days)), _xlfn.LET( _xlpm.txt, C40, _xlpm.y, RIGHT(_xlpm.txt,4)*1, _xlpm.m, LEFT(_xlpm.txt, FIND("/",_xlpm.txt)-1)*1, _xlpm.d, MID(_xlpm.txt, FIND("/",_xlpm.txt)+1, FIND("/",_xlpm.txt, FIND("/",_xlpm.txt)+1) - FIND("/",_xlpm.txt) -1 )*1, _xlpm.days, DATE(_xlpm.y,_xlpm.m,_xlpm.d) - TODAY(), IF(_xlpm.days<0, "Expired", _xlpm.days) ) ) )
A41: =IF(B41="","-",IF(COUNTIF(E.DETACHED!B:B,B41)+COUNTIF('A.S.PRINTOUT'!B:B,B41)>1,COUNTIF(E.DETACHED!B:B,B41)+COUNTIF('A.S.PRINTOUT'!B:B,B41)-1,"-")) | B41: 4701 RIDGELAWN DRIVE | C41: 4/30/2026 | D41: 5500000 | E41: 45778 | F41: =IF(E41="","",MAX(0, TODAY() - IF(ISNUMBER(E41), E41, IFERROR( DATEVALUE(SUBSTITUTE(E41,CHAR(160)," ")), DATE(VALUE(RIGHT(E41,4)), VALUE(LEFT(E41,FIND("/",E41)-1)), VALUE(MID(E41,FIND("/",E41)+1, FIND("/",E41, FIND("/",E41)+1)-FIND("/",E41)-1)) ) ) ) )) | G41: 1 | H41: 1955 | I41: 7168 | J41: 4 | K41: 2 | L41: 2779 | M41: 2 | N41: 1982000 | O41: 2083000 | P41: =IF(C41="","", IF(ISNUMBER(C41), _xlfn.LET(_xlpm.days, C41 - TODAY(), IF(_xlpm.days<0, "Expired", _xlpm.days)), _xlfn.LET( _xlpm.txt, C41, _xlpm.y, RIGHT(_xlpm.txt,4)*1, _xlpm.m, LEFT(_xlpm.txt, FIND("/",_xlpm.txt)-1)*1, _xlpm.d, MID(_xlpm.txt, FIND("/",_xlpm.txt)+1, FIND("/",_xlpm.txt, FIND("/",_xlpm.txt)+1) - FIND("/",_xlpm.txt) -1 )*1, _xlpm.days, DATE(_xlpm.y,_xlpm.m,_xlpm.d) - TODAY(), IF(_xlpm.days<0, "Expired", _xlpm.days) ) ) ) | Q41: LA
...

Sheet E.DETACHED
B1: BRENTWOOD PARK - BURNABY NORTH
B2: Subject Property | C2: Expiry | D2: List | E2: L.Date | F2: DOM | G2: List# | H2: Build | I2: Lot Size | J2: Bed | K2: Bath | L2: Sqft | M2: Kitch | N2: Land | O2: Total ASS | P2: D.EXP | Q2: Contact | R2: ML# | S2: NAME | T2: ADDRESS1 | U2: ADDRESS2 | V2: OCCUP
B3: EXPIRED: | C3: ="Date Range: " & TEXT(TODAY()-30, "MMMM DD, YYYY") & " - " & TEXT(TODAY(), "MMMM DD, YYYY") & " (LAST 30 DAYS)"
A4: =IF(B4="","-",IF(COUNTIF(E.DETACHED!B:B,B4)+COUNTIF('A.S.PRINTOUT'!B:B,B4)>1,COUNTIF(E.DETACHED!B:B,B4)+COUNTIF('A.S.PRINTOUT'!B:B,B4)-1,"-")) | B4: 4645 BRENTLAWN DRIVE | C4: 46112 | D4: 4000000 | E4: 45736 | F4: 377 | H4: 1954 | I4: 6466 | J4: 4 | K4: 4 | L4: 2024 | M4: 3 | N4: 1789000 | O4: 1899000 | P4: Expired | R4: R2980434,
A5: =IF(B5="","-",IF(COUNTIF(E.DETACHED!B:B,B5)+COUNTIF('A.S.PRINTOUT'!B:B,B5)>1,COUNTIF(E.DETACHED!B:B,B5)+COUNTIF('A.S.PRINTOUT'!B:B,B5)-1,"-"))
A6: =IF(B6="","-",IF(COUNTIF(E.DETACHED!B:B,B6)+COUNTIF('A.S.PRINTOUT'!B:B,B6)>1,COUNTIF(E.DETACHED!B:B,B6)+COUNTIF('A.S.PRINTOUT'!B:B,B6)-1,"-"))
A7: =IF(B7="","-",IF(COUNTIF(E.DETACHED!B:B,B7)+COUNTIF('A.S.PRINTOUT'!B:B,B7)>1,COUNTIF(E.DETACHED!B:B,B7)+COUNTIF('A.S.PRINTOUT'!B:B,B7)-1,"-"))
A8: =IF(B8="","-",IF(COUNTIF(E.DETACHED!B:B,B8)+COUNTIF('A.S.PRINTOUT'!B:B,B8)>1,COUNTIF(E.DETACHED!B:B,B8)+COUNTIF('A.S.PRINTOUT'!B:B,B8)-1,"-"))
B9: Subject Property | C9: Expiry | D9: List | E9: L.Date | F9: DOM | G9: List# | H9: Build | I9: Lot Size | J9: Bed | K9: Bath | L9: Sqft | M9: Kitch | N9: Land | O9: Total ASS | P9: D.EXP | Q9: Contact | R9: ML# | S9: NAME | T9: ADDRESS1 | U9: ADDRESS2 | V9: OCCUP | W9: Notes
B10: EXPIRED: | C10: ="Date Range: " & "December 31 2014" & " - " & TEXT(TODAY()-30, "MMMM DD, YYYY")
A11: =IF(B11="","-",IF(COUNTIF(E.DETACHED!B:B,B11)+COUNTIF('A.S.PRINTOUT'!B:B,B11)>1,COUNTIF(E.DETACHED!B:B,B11)+COUNTIF('A.S.PRINTOUT'!B:B,B11)-1,"-")) | B11: 1740 BETA AVENUE | C11: 5/15/2023 | D11: 2799999 | Q11: F - 03.25.25 | R11: R2752689, | S11: GI HOON YU | SOYON LEE | KANGHUN LEE | T11: 1740 BETA AVENUE | U11: BURNABY BC V5C 5M7 | V11: V
A12: =IF(B12="","-",IF(COUNTIF(E.DETACHED!B:B,B12)+COUNTIF('A.S.PRINTOUT'!B:B,B12)>1,COUNTIF(E.DETACHED!B:B,B12)+COUNTIF('A.S.PRINTOUT'!B:B,B12)-1,"-")) | B12: 4508 BRENTLAWN DRIVE | C12: 9/1/2016 | D12: 1480000 | Q12: F - 03.25.25 | R12: R2099852, | S12: Home Owner | T12: 4508 BRENTLAWN DRIVE | U12: BURNABY BC V5C 3V1 | V12: V
A13: =IF(B13="","-",IF(COUNTIF(E.DETACHED!B:B,B13)+COUNTIF('A.S.PRINTOUT'!B:B,B13)>1,COUNTIF(E.DETACHED!B:B,B13)+COUNTIF('A.S.PRINTOUT'!B:B,B13)-1,"-")) | B13: 4625 BRENTLAWN DRIVE | C13: 1/31/2023 | D13: 1998800 | R13: R2728909, | S13: Home Owner | T13: 4625 BRENTLAWN DRIVE | U13: BURNABY BC V5C 3V3 | V13: OT
A14: =IF(B14="","-",IF(COUNTIF(E.DETACHED!B:B,B14)+COUNTIF('A.S.PRINTOUT'!B:B,B14)>1,COUNTIF(E.DETACHED!B:B,B14)+COUNTIF('A.S.PRINTOUT'!B:B,B14)-1,"-")) | B14: 1050 DELTA AVENUE | C14: 5/12/2022 | D14: 2398000 | Q14: F - 03.25.25 | R14: R2674452, | S14: E. PAPALIA | T14: 1050 DELTA AVENUE | U14: BURNABY BC V5B 3G1 | V14: O
A15: =IF(B15="","-",IF(COUNTIF(E.DETACHED!B:B,B15)+COUNTIF('A.S.PRINTOUT'!B:B,B15)>1,COUNTIF(E.DETACHED!B:B,B15)+COUNTIF('A.S.PRINTOUT'!B:B,B15)-1,"-")) | B15: 1678 DELTA AVENUE | C15: 6/16/2018 | D15: 2380000 | Q15: F - 03.25.25 | R15: R2248669, | S15: SHAKILA JEYACHANDRAN | T15: 1678 DELTA AVENUE | U15: BURNABY BC V5B 3G2 | V15: O
A16: =IF(B16="","-",IF(COUNTIF(E.DETACHED!B:B,B16)+COUNTIF('A.S.PRINTOUT'!B:B,B16)>1,COUNTIF(E.DETACHED!B:B,B16)+COUNTIF('A.S.PRINTOUT'!B:B,B16)-1,"-")) | B16: 4696 FAIRLAWN DRIVE | C16: 8/18/2021 | D16: 1749900 | Q16: F - 03.25.25 | R16: R2589225, | S16: Home Owner | T16: 4696 FAIRLAWN DRIVE | U16: BURNABY BC V5C 3R6 | V16: O
A17: =IF(B17="","-",IF(COUNTIF(E.DETACHED!B:B,B17)+COUNTIF('A.S.PRINTOUT'!B:B,B17)>1,COUNTIF(E.DETACHED!B:B,B17)+COUNTIF('A.S.PRINTOUT'!B:B,B17)-1,"-")) | B17: 4824 FAIRLAWN DRIVE | C17: 11/14/2024 | D17: 2558000 | Q17: F - 03.25.25 | R17: R2911387, | S17: PAI LIU | T17: 4824 FAIRLAWN DRIVE | U17: BURNABY BC V5C 3R8 | V17: OT
A18: =IF(B18="","-",IF(COUNTIF(E.DETACHED!B:B,B18)+COUNTIF('A.S.PRINTOUT'!B:B,B18)>1,COUNTIF(E.DETACHED!B:B,B18)+COUNTIF('A.S.PRINTOUT'!B:B,B18)-1,"-")) | B18: 5173 HALIFAX STREET | C18: 10/31/2017 | D18: 1799000 | Q18: F - 03.25.25 | R18: R2193437, | S18: Home Owner | T18: 5173 HALIFAX STREET | U18: Burnaby, BC V5B 2N4 | V18: O
A19: =IF(B19="","-",IF(COUNTIF(E.DETACHED!B:B,B19)+COUNTIF('A.S.PRINTOUT'!B:B,B19)>1,COUNTIF(E.DETACHED!B:B,B19)+COUNTIF('A.S.PRINTOUT'!B:B,B19)-1,"-")) | B19: 4631 HIGHLAWN DRIVE | C19: 12/31/2016 | D19: 3888000 | Q19: F - 03.25.25 | R19: R2062861, | S19: M. QUATRANO | V. HRELIA | T19: 4631 HIGHLAWN DRIVE | U19: Burnaby, BC V5C 3S9 | V19: O
A20: =IF(B20="","-",IF(COUNTIF(E.DETACHED!B:B,B20)+COUNTIF('A.S.PRINTOUT'!B:B,B20)>1,COUNTIF(E.DETACHED!B:B,B20)+COUNTIF('A.S.PRINTOUT'!B:B,B20)-1,"-")) | B20: 4881 HIGHLAWN DRIVE | C20: 8/20/2024 | D20: 1950000 | Q20: F - 03.25.25 | R20: R2914527, | S20: T. Lin & Y. Yang | T20: 4881 HIGHLAWN DRIVE | U20: BURNABY BC V5C 3T2 | V20: T
A21: =IF(B21="","-",IF(COUNTIF(E.DETACHED!B:B,B21)+COUNTIF('A.S.PRINTOUT'!B:B,B21)>1,COUNTIF(E.DETACHED!B:B,B21)+COUNTIF('A.S.PRINTOUT'!B:B,B21)-1,"-")) | B21: 4606 MIDLAWN DRIVE | C21: 45859 | D21: 7800000 | R21: R2951904, | S21: HAN YUN YAN | SHAO BIN ZHANG | T21: 4606 MIDLAWN DRIVE | U21: Burnaby, BC V5C 3P6 | V21: O
A22: =IF(B22="","-",IF(COUNTIF(E.DETACHED!B:B,B22)+COUNTIF('A.S.PRINTOUT'!B:B,B22)>1,COUNTIF(E.DETACHED!B:B,B22)+COUNTIF('A.S.PRINTOUT'!B:B,B22)-1,"-")) | B22: 4660 NORTHLAWN DRIVE | C22: 5/29/2022 | D22: 2188000 | Q22: F - 03.25.25 | R22: R2637059, | S22: Shuming WANG & Weiwei WANG | T22: 4660 NORTHLAWN DRIVE | U22: BURNABY BC V5C 3S1 | V22: T
A23: =IF(B23="","-",IF(COUNTIF(E.DETACHED!B:B,B23)+COUNTIF('A.S.PRINTOUT'!B:B,B23)>1,COUNTIF(E.DETACHED!B:B,B23)+COUNTIF('A.S.PRINTOUT'!B:B,B23)-1,"-")) | B23: 4825 NORTHLAWN DRIVE | C23: 10/28/2021 | D23: 2800000 | Q23: F - 03.25.25 | R23: R2512957, | S23: Trung Kiet Do | T23: 4825 NORTHLAWN DRIVE | U23: BURNABY BC V5C 3S2 | V23: O
A24: =IF(B24="","-",IF(COUNTIF(E.DETACHED!B:B,B24)+COUNTIF('A.S.PRINTOUT'!B:B,B24)>1,COUNTIF(E.DETACHED!B:B,B24)+COUNTIF('A.S.PRINTOUT'!B:B,B24)-1,"-")) | B24: 4532 PARKER STREET | C24: 9/7/2021 | D24: 1890000 | Q24: F - 03.25.25 | R24: R2608888, | S24: Home Owner | T24: 4532 PARKER STREET | U24: BURNABY BC V5C 3C9 | V24: OT
A25: =IF(B25="","-",IF(COUNTIF(E.DETACHED!B:B,B25)+COUNTIF('A.S.PRINTOUT'!B:B,B25)>1,COUNTIF(E.DETACHED!B:B,B25)+COUNTIF('A.S.PRINTOUT'!B:B,B25)-1,"-")) | B25: 4578 PARKER STREET | C25: 4/25/2022 | D25: 2499888 | Q25: F - 03.25.25 | R25: R2571778, | S25: Home Owner | T25: 4578 PARKER STREET | U25: BURNABY BC V5C 3C9 | V25: O
A26: =IF(B26="","-",IF(COUNTIF(E.DETACHED!B:B,B26)+COUNTIF('A.S.PRINTOUT'!B:B,B26)>1,COUNTIF(E.DETACHED!B:B,B26)+COUNTIF('A.S.PRINTOUT'!B:B,B26)-1,"-")) | B26: 4764 PARKER STREET | C26: 10/7/2022 | D26: 2088000 | Q26: F - 03.25.25 | R26: R2708274, | S26: Home Owner | T26: 4764 PARKER STREET | U26: BURNABY BC V5C 3E3 | V26: O
A27: =IF(B27="","-",IF(COUNTIF(E.DETACHED!B:B,B27)+COUNTIF('A.S.PRINTOUT'!B:B,B27)>1,COUNTIF(E.DETACHED!B:B,B27)+COUNTIF('A.S.PRINTOUT'!B:B,B27)-1,"-")) | B27: 4840 PARKER STREET | C27: 9/30/2025 | D27: 1990000 | E27: 7/24/2024 | F27: =IF(E27="","",MAX(0, TODAY() - IF(ISNUMBER(E27), E27, IFERROR( DATEVALUE(SUBSTITUTE(E27,CHAR(160)," ")), DATE(VALUE(RIGHT(E27,4)), VALUE(LEFT(E27,FIND("/",E27)-1)), VALUE(MID(E27,FIND("/",E27)+1, FIND("/",E27, FIND("/",E27)+1)-FIND("/",E27)-1)) ) ) ) )) | G27: 1 | H27: 1960 | I27: 6100 | J27: 2 | K27: 2 | L27: 2240 | M27: 1 | N27: 1724000 | O27: 1775500 | P27: =IF(TRIM(C27)="","", IFERROR( IF( DATE( VALUE(RIGHT(TRIM(C27),4)), VALUE(LEFT(TRIM(C27),FIND("/",TRIM(C27))-1)), VALUE(MID(TRIM(C27),FIND("/",TRIM(C27))+1, FIND("/",TRIM(C27),FIND("/",TRIM(C27))+1)-FIND("/",TRIM(C27))-1)) ) < TODAY(), "Expired", DATE( VALUE(RIGHT(TRIM(C27),4)), VALUE(LEFT(TRIM(C27),FIND("/",TRIM(C27))-1)), VALUE(MID(TRIM(C27),FIND("/",TRIM(C27))+1, FIND("/",TRIM(C27),FIND("/",TRIM(C27))+1)-FIND("/",TRIM(C27))-1)) ) - TODAY() ), "" ) ) | R27: R2909143, | S27: VANI MAN | VINCENT LAI | T27: 4840 PARKER STREET | U27: BURNABY, BC V5C 3E3 | V27: V
A28: =IF(B28="","-",IF(COUNTIF(E.DETACHED!B:B,B28)+COUNTIF('A.S.PRINTOUT'!B:B,B28)>1,COUNTIF(E.DETACHED!B:B,B28)+COUNTIF('A.S.PRINTOUT'!B:B,B28)-1,"-")) | B28: 4915 PARKER STREET | C28: 12/30/2018 | D28: 1648800 | Q28: F - 03.25.25 | R28: R2264729, | S28: Home Owner | T28: 4915 PARKER STREET | U28: BURNABY BC V5B 1Z5 | V28: O
A29: =IF(B29="","-",IF(COUNTIF(E.DETACHED!B:B,B29)+COUNTIF('A.S.PRINTOUT'!B:B,B29)>1,COUNTIF(E.DETACHED!B:B,B29)+COUNTIF('A.S.PRINTOUT'!B:B,B29)-1,"-")) | B29: 5190 PARKER STREET | C29: 3/31/2019 | D29: 1399000 | Q29: F - 03.25.25 | R29: R2310986, | S29: Home Owner | T29: 5190 PARKER STREET | U29: BURNABY BC V5B 1Z6 | V29: O
A30: =IF(B30="","-",IF(COUNTIF(E.DETACHED!B:B,B30)+COUNTIF('A.S.PRINTOUT'!B:B,B30)>1,COUNTIF(E.DETACHED!B:B,B30)+COUNTIF('A.S.PRINTOUT'!B:B,B30)-1,"-")) | B30: 4801 RIDGELAWN DRIVE | C30: 12/14/2017 | D30: 2488000 | Q30: F - 03.25.25 | R30: R2178230, | S30: PATCHARA SRIKITKUL | T30: 4801 RIDGELAWN DRIVE | U30: BURNABY BC V5C 3Y1 | V30: O
A31: =IF(B31="","-",IF(COUNTIF(E.DETACHED!B:B,B31)+COUNTIF('A.S.PRINTOUT'!B:B,B31)>1,COUNTIF(E.DETACHED!B:B,B31)+COUNTIF('A.S.PRINTOUT'!B:B,B31)-1,"-")) | B31: 1333 SPRINGER AVENUE | C31: 5/30/2016 | D31: 1588000 | Q31: F - 03.25.25 | R31: R2035899, | S31: M. MOTEVASELAN | T31: 1333 SPRINGER AVENUE | U31: Burnaby, BC V5B 3M2 | V31: O
A32: =IF(B32="","-",IF(COUNTIF(E.DETACHED!B:B,B32)+COUNTIF('A.S.PRINTOUT'!B:B,B32)>1,COUNTIF(E.DETACHED!B:B,B32)+COUNTIF('A.S.PRINTOUT'!B:B,B32)-1,"-")) | B32: 4542 UNION STREET | C32: 2/28/2018 | D32: 1898000 | R32: R2204592, | S32: PARADISE PROPERTIES LTD. | T32: 4542 UNION STREET | U32: Burnaby, BC V5C 2Y1 | V32: V
A33: =IF(B33="","-",IF(COUNTIF(E.DETACHED!B:B,B33)+COUNTIF('A.S.PRINTOUT'!B:B,B33)>1,COUNTIF(E.DETACHED!B:B,B33)+COUNTIF('A.S.PRINTOUT'!B:B,B33)-1,"-")) | B33: 4890 UNION STREET | C33: 3/7/2021 | D33: 1399000 | R33: R2527115, | S33: Home Owner | T33: 4890 UNION STREET | U33: BURNABY BC V5C 2Y6
A34: =IF(B34="","-",IF(COUNTIF(E.DETACHED!B:B,B34)+COUNTIF('A.S.PRINTOUT'!B:B,B34)>1,COUNTIF(E.DETACHED!B:B,B34)+COUNTIF('A.S.PRINTOUT'!B:B,B34)-1,"-")) | B34: 5030 UNION STREET | C34: 2/18/2020 | D34: 1880000 | Q34: F - 03.25.25 | R34: R2397711, | S34: Home Owner | T34: 5030 UNION STREET | U34: Burnaby, BC V5B 1W2 | V34: OT
A35: =IF(B35="","-",IF(COUNTIF(E.DETACHED!B:B,B35)+COUNTIF('A.S.PRINTOUT'!B:B,B35)>1,COUNTIF(E.DETACHED!B:B,B35)+COUNTIF('A.S.PRINTOUT'!B:B,B35)-1,"-")) | B35: 4856 VENABLES STREET | C35: 6/30/2021 | D35: 2880000 | Q35: F - 03.25.25 | R35: R2548421, | S35: Home Owner | T35: 4856 VENABLES STREET | U35: BURNABY BC V5C 3A8 | V35: O
A36: =IF(B36="","-",IF(COUNTIF(E.DETACHED!B:B,B36)+COUNTIF('A.S.PRINTOUT'!B:B,B36)>1,COUNTIF(E.DETACHED!B:B,B36)+COUNTIF('A.S.PRINTOUT'!B:B,B36)-1,"-")) | B36: 4921 VENABLES STREET | C36: 12/31/2023 | D36: 3988000 | Q36: F - 03.25.25 | R36: R2800937, | S36: Home Owner | T36: 4921 VENABLES STREET | U36: BURNABY BC V5B 1X8 | V36: O
A37: =IF(B37="","-",IF(COUNTIF(E.DETACHED!B:B,B37)+COUNTIF('A.S.PRINTOUT'!B:B,B37)>1,COUNTIF(E.DETACHED!B:B,B37)+COUNTIF('A.S.PRINTOUT'!B:B,B37)-1,"-")) | B37: 4699 WESTLAWN DRIVE | C37: 8/31/2021 | D37: 1899900 | R37: R2579943, | S37: Gloria Di Persico & Angelo Di Persico | T37: 4699 WESTLAWN DRIVE | U37: BURNABY BC V5C 3R2 | V37: O
A38: =IF(B38="","-",IF(COUNTIF(E.DETACHED!B:B,B38)+COUNTIF('A.S.PRINTOUT'!B:B,B38)>1,COUNTIF(E.DETACHED!B:B,B38)+COUNTIF('A.S.PRINTOUT'!B:B,B38)-1,"-")) | B38: 4730 WESTLAWN DRIVE | C38: 5/28/2024 | D38: 1799800 | R38: R2883993, | S38: Home Owner | T38: 4730 WESTLAWN DRIVE | U38: BURNABY BC V5C 3R3 | V38: T
A39: =IF(B39="","-",IF(COUNTIF(E.DETACHED!B:B,B39)+COUNTIF('A.S.PRINTOUT'!B:B,B39)>1,COUNTIF(E.DETACHED!B:B,B39)+COUNTIF('A.S.PRINTOUT'!B:B,B39)-1,"-")) | B39: 4645 BRENTLAWN DRIVE | C39: 46112 | D39: 4000000 | E39: 45736 | F39: 377 | H39: 1954 | I39: 6466 | J39: 4 | K39: 4 | L39: 2024 | M39: 3 | N39: 1789000 | O39: 1899000 | P39: 11 | R39: R2980434,
A40: =IF(B40="","-",IF(COUNTIF(E.DETACHED!B:B,B40)+COUNTIF('A.S.PRINTOUT'!B:B,B40)>1,COUNTIF(E.DETACHED!B:B,B40)+COUNTIF('A.S.PRINTOUT'!B:B,B40)-1,"-"))
...

Sheet E.ATTACHED
A1: Audit | B1: Expiration | C1: MLS# | D1: Subject Property | E1: Address1 | F1: Address2 | G1: Price | H1: Name | I1: Occupancy | J1: Title | K1: Notes | L1: Rating | M1: Flyer | N1: Contact | O1: Mobile | P1: Email
A2: 2 Bed 2 Bath
A4: 4.7.25 | B4: 45749 | C4: R2953905, | D4: 704 4433 ALASKA STREET | E4: 500 856 HOMER STREET | F4: Vancouver, BC V5B 2W6 | G4: 959900 | H4: AMACON DEVELOPMENT (ALASKA CORP) | I4: V | J4: Y | K4: E | L4: (Developer)
A5: 4.7.25 | B5: 45749 | C5: R2953901, | D5: 1702 4433 ALASKA STREET | E5: 500 856 HOMER STREET | F5: Vancouver, BC V5B 2W6 | G5: 945900 | H5: AMACON DEVELOPMENT (ALASKA CORP) | I5: V | J5: Y | K5: E | L5: (Developer)
A6: 4.7.25 | B6: 45749 | C6: R2953904, | D6: 1802 4433 ALASKA STREET | E6: 500 856 HOMER STREET | F6: Vancouver, BC V5B 2W6 | G6: 949400 | H6: AMACON DEVELOPMENT (ALASKA CORP) | I6: V | J6: Y | K6: E | L6: (Developer)
A7: 4.7.25 | B7: 12.26.24 | C7: R2899247, | D7: 309 4768 BRENTWOOD DRIVE | E7: 309 4768 BRENTWOOD DRIVE | F7: BURNABY BC V5C 0C7 | G7: 729900 | H7: CUI YAN MA | ZHUO WEN ZHOU | I7: T | J7: Y
A8: 4.7.25 | B8: 02.19.25 | C8: R2916804, | D8: 201 4788 BRENTWOOD DRIVE | E8: 201 4788 BRENTWOOD DRIVE | F8: BURNABY BC V5C 0C5 | G8: 729000 | H8: TRAN MY THI TRAN | I8: O | J8: Y
A9: 4.7.25 | B9: 02.12.25 | C9: R2849630, | D9: 2802 4400 BUCHANAN STREET | E9: 2802 4400 BUCHANAN STREET | F9: BURNABY BC V5C 0E3 | G9: 1880000 | H9: HO SUEN | MEI YUN QIAN | I9: T | J9: Y | K9: 3BR
A10: 4.7.25 | B10: 02.20.25 | C10: R2851939, | D10: 2802 2133 DOUGLAS ROAD | E10: 2802 2133 DOUGLAS ROAD | F10: BURNABY BC V5C 0E9 | G10: 938000 | H10: CHEN, JU | I10: T | J10: Y
A11: 4.7.25 | B11: 01.03.25 | C11: R2945361, | D11: 405 1728 GILMORE AVENUE | E11: 405 1728 GILMORE AVENUE | F11: BURNABY, BC V5C 0L3 | G11: 848800 | H11: PARMJIT SAGGU & VIKRAM SAGGU & JASBINDER PANESAR | I11: O | J11: Y | K11: CP
A12: 4.7.25 | B12: 12.31.24 | C12: R2912174, | D12: 1505 2186 GILMORE AVENUE | E12: 5339 MONARCH STREET | F12: BURNABY, BC V5G 1Z9 | G12: 1068000 | H12: KUN HO KU | I12: V | J12: Y
A13: 4.7.25 | B13: 12.31.24 | C13: R2914218, | D13: 2608 2186 GILMORE AVENUE | E13: 2608 2186 GILMORE AVENUE | F13: Burnaby, BC V5C 0N7 | G13: 1050000 | H13: Home Owner | I13: V | J13: N
A14: 4.7.25 | B14: 01.31.25 | C14: R2908605, | D14: 4507 2186 GILMORE AVENUE | E14: 2003 4250 DAWSON ST | F14: BURNABY, BC V5C 4B1 | G14: 1278000 | H14: SHAHRAM FASIHY | I14: O | J14: Y | M14: 04.02.25
A15: 4.7.25 | B15: 01.31.25 | C15: R2908621, | D15: 4607 2186 GILMORE AVENUE | E15: 2003 4250 DAWSON ST | F15: BURNABY, BC V5C 4B1 | G15: 1288000 | H15: SHAHRAM FASIHY | I15: O | J15: Y | M15: 04.02.25
A16: 4.7.25 | B16: 02.26.25 | C16: R2918659, | D16: 4709 2186 GILMORE AVENUE | E16: 701-8260 162A STREET | F16: SURREY, BC V4N 0P6 | G16: 899000 | H16: IZAK HALIGVA | I16: V | J16: Y
A17: 4.7.25 | B17: 12.31.24 | C17: R2898031, | D17: 2301 5311 GORING STREET | E17: 2301 5311 GORING STREET | F17: Burnaby, BC V5B 0B5 | G17: 1499900 | H17: MOHAMMAD ANSAR | I17: O | J17: Y
A18: 4.7.25 | B18: 03.01.25 | C18: R2944836, | D18: 1204 2225 HOLDOM AVENUE | E18: 1204 2225 HOLDOM AVENUE | F18: Burnaby, BC V5B 0A1 | G18: 879900 | H18: ALIREZA RABIEE | I18: V | J18: Y
A19: 4.7.25 | B19: 03.04.25 | C19: R2944216, | D19: 1308 4488 JUNEAU STREET | E19: 1308 4488 JUNEAU STREET | F19: Burnaby, BC V5C 0M4 | G19: 928000 | H19: PHILLIP ROY LUNDRIE | HUI XIN ZHONG | I19: O | J19: Y
A20: 4.7.25 | B20: 01.27.25 | C20: R2920074, | D20: 701 4488 JUNEAU STREET | E20: 701 4488 JUNEAU STREET | F20: BURNABY, BC V5C 0M4 | G20: 949900 | H20: CARMELA DE BENEDETTO | I20: V | J20: Y
A21: 4.7.25 | B21: 45748 | C21: R2948501, | D21: 1306 4168 LOUGHEED HIGHWAY | E21: 1306 4168 LOUGHEED HIGHWAY | F21: Burnaby, BC V5C 0N9 | G21: 938888 | H21: ONNI GILMORE HOLDINGS CORP | I21: V | J21: Y | K21: E | L21: (Developer)
A22: 4.7.25 | B22: 03.01.25 | C22: R2949136, | D22: 2107 4168 LOUGHEED HIGHWAY | E22: 201 1280 RICHARDS ST | F22: VANCOUVER, BC V6B 1S2 | G22: 990000 | H22: BRUC LEONARD HOBSON | VICTORIA CAROLINA OSORIO SANCHEZ | I22: V | J22: Y
A23: 4.7.25 | B23: 01.22.25 | C23: R2917054, | D23: 2409 4880 LOUGHEED HIGHWAY | E23: 3968 WEST 11th AVENUE | F23: VANCOUVER, BC V6R 2L2 | G23: 893000 | H23: XI YU GUO | I23: V | J23: Y
A24: 4.7.25 | B24: 12.31.24 | C24: R2866736, | D24: 3003 4880 LOUGHEED HIGHWAY | E24: 3003 4880 LOUGHEED HIGHWAY | F24: Burnaby, BC V5C 0N1 | G24: 988000 | H24: Home Owner | I24: V | J24: Y (developer)
A25: 4.7.25 | B25: 12.31.24 | C25: R2868864, | D25: 4102 4880 LOUGHEED HIGHWAY | E25: 4102 4880 LOUGHEED HIGHWAY | F25: Burnaby, BC V5C 0N1 | G25: 999000 | H25: Home Owner | I25: V | J25: N
A26: 4.7.25 | B26: 12.31.24 | C26: R2866541, | D26: 4202 4880 LOUGHEED HIGHWAY | E26: 4202 4880 LOUGHEED HIGHWAY | F26: Burnaby, BC V5C 0N1 | G26: 1048000 | H26: Home Owner | I26: V | J26: Y (developer)
A27: 4.7.25 | B27: 45748 | C27: R2950958, | D27: 1604 4890 LOUGHEED HIGHWAY | E27: 2607 4890 LOUGHEED HIGHWAY | F27: Burnaby, BC V5C 0N2 | G27: 899800 | H27: HO MAN MAK | I27: V | J27: Y | K27: E
A28: 4.7.25 | B28: 12.31.24 | C28: R2900969, | D28: 3302 4890 LOUGHEED HIGHWAY | E28: 3551 SHUSWAP AVENUE | F28: RICHMOND, BC V7E 2A9 | G28: 1008000 | H28: CHI KEUNG CHENG | I28: V | J28: Y
A29: 4.7.25 | B29: 12.31.24 | C29: R2875051, | D29: 3503 4890 LOUGHEED HIGHWAY | E29: 3503 - 4890 LOUGHEED HIGHWAY | F29: BURNABY, BC V5C 0N2 | G29: 1350000 | H29: YOU HUA HUANG | I29: V | J29: Y
A30: 4.7.25 | B30: 12.31.24 | C30: R2867661, | D30: 3409 4880 LOUGHEED HIGHWAY | E30: 7560 TWEEDSMUIR AVE | F30: RICHMOND, BC V7A 5G6 | G30: 968000 | H30: HUI ZHEN CHEN | I30: V | J30: Y
A31: 4.7.25 | B31: 01.03.25 | C31: R2916789, | D31: 3002 2181 MADISON AVENUE | E31: 3002 2181 MADISON AVENUE | F31: BURNABY, BC V5C 0N4 | G31: 989000 | H31: YANAN ZHA | I31: V | J31: Y
B32: 07.23.23 | C32: R2766903, | D32: 506 2188 MADISON AVENUE | E32: 506 2188 MADISON AVENUE | F32: Burnaby, BC V5C 0J8 | G32: 998000 | H32: Home Owner | I32: O | J32: N | K32: T | M32: 04.16.25
A33: 4.7.25 | B33: 12.27.24 | C33: R2913276, | D33: 511 2188 MADISON AVENUE | E33: 4135 GEORGIA STREET | F33: BURNABY, BC V5C 2T5 | G33: 893888 | H33: RICK MANGAT | TINA MARIA CIACCIA MANGAT | I33: T | J33: Y | M33: 04.16.25
A34: 4.7.25 | B34: 45751 | C34: R2963413, | D34: 3009 2181 MADISON AVENUE | E34: 4858 GEORGIA STREET | F34: Burnaby, BC V5C 2V9 | G34: 838000 | H34: DAN TAK-YAN CHEUK | SAU CHU TSUI | I34: V | J34: Y | K34: E
A35: 4.7.25 | B35: 01.31.25 | C35: R2940862, | D35: 1901 2388 MADISON AVENUE | E35: 8855 151 ST | F35: SURREY, BC V3R 6X5 | G35: 939000 | H35: YANGYU LI | I35: T | J35: Y
A36: 4.7.25 | B36: 02.18.25 | C36: R2944995, | D36: 1405 2085 SKYLINE COURT | E36: 10208 170A STREET | F36: SURREY, BC V4N 4N6 | G36: 998800 | H36: SHI HAI HUANG | XIAO GUANG CHI | I36: T | J36: Y
A37: 4.7.25 | B37: 12.31.24 | C37: R2916186, | D37: 2704 2085 SKYLINE COURT | E37: 2704 2085 SKYLINE COURT | F37: Burnaby, BC V5C 0M6 | G37: 1156000 | H37: FENGYU CHEN | I37: TV | J37: Y
A38: 4.7.25 | B38: 45750 | C38: R2964733, | D38: 4005 4485 SKYLINE DRIVE | E38: 4005 4485 SKYLINE DRIVE | F38: Burnaby, BC V5C 0J2 | G38: 938888 | H38: XIAOMIN RONG | I38: O | J38: Y | K38: T
A39: 4.7.25 | B39: 12.31.24 | C39: R2899448, | D39: 4604 4485 SKYLINE DRIVE | E39: 4604 4485 SKYLINE DRIVE | F39: Burnaby, BC V5C 0J2 | G39: 1038000 | H39: JASON JAEHO LEE | I39: O | J39: Y
A40: 4.7.25 | B40: 45748 | C40: R2911083, | D40: 1102 2289 YUKON CRESCENT | E40: 203 2533 PENTICTON STREET | F40: Vancouver, BC V5M 4T8 | G40: 679000 | H40: YING ZHUANG | HUI ZHUANG | I40: O | J40: Y | K40: E
A42: 4.7.25 | B42: 45130 | C42: R2766903, | D42: 506 2188 MADISON AVENUE | E42: 506 2188 MADISON AVENUE | F42: Burnaby, BC V5C 0J8 | G42: 998000 | H42: Home Owner | I42: O | J42: N | K42: T
...

Sheet PROSPECTS
A1: GOOGLE MAP - BRENTWOOD PARK
A2: BC ASSESSMENT - BRENTWOOD PARK
A4: Audit | B4: Expiration | C4: MLS# | D4: Address | E4: Price | F4: Name | G4: Occupancy | H4: Title | I4: Rating | J4: Flyer | K4: Contact | L4: Mobile | M4: Email | N4: Notes
D6: 4795 Westlawn Dr | F6: Ron | N6: door knocked

Sheet PRINT
A1: Audit | B1: Expiration | C1: MLS# | D1: Subject Property | E1: Address1 | F1: Address2 | G1: Price | H1: Name
A2: DETACHED
A3: 03.23.25 | B3: 5/15/2023 | C3: R2752689, | D3: 1740 BETA AVENUE | E3: 1740 BETA AVENUE | F3: BURNABY BC V5C 5M7 | G3: 2799999 | H3: GI HOON YU | SOYON LEE | KANGHUN LEE
A4: 03.23.25 | B4: 9/1/2016 | C4: R2099852, | D4: 4508 BRENTLAWN DRIVE | E4: 4508 BRENTLAWN DRIVE | F4: BURNABY BC V5C 3V1 | G4: 1480000 | H4: Home Owner
A5: 03.23.25 | B5: 5/12/2022 | C5: R2674452, | D5: 1050 DELTA AVENUE | E5: 1050 DELTA AVENUE | F5: BURNABY BC V5B 3G1 | G5: 2398000 | H5: E. PAPALIA
A6: 03.23.25 | B6: 6/16/2018 | C6: R2248669, | D6: 1678 DELTA AVENUE | E6: 1678 DELTA AVENUE | F6: BURNABY BC V5B 3G2 | G6: 2380000 | H6: SHAKILA JEYACHANDRAN
A7: 03.23.25 | B7: 8/18/2021 | C7: R2589225, | D7: 4696 FAIRLAWN DRIVE | E7: 4696 FAIRLAWN DRIVE | F7: BURNABY BC V5C 3R6 | G7: 1749900 | H7: Home Owner
A8: 03.23.25 | B8: 11/14/2024 | C8: R2911387, | D8: 4824 FAIRLAWN DRIVE | E8: 4824 FAIRLAWN DRIVE | F8: BURNABY BC V5C 3R8 | G8: 2558000 | H8: PAI LIU
A9: 03.23.25 | B9: 10/31/2017 | C9: R2193437, | D9: 5173 HALIFAX STREET | E9: 5173 HALIFAX STREET | F9: Burnaby, BC V5B 2N4 | G9: 1799000 | H9: Home Owner
A10: 03.23.25 | B10: 12/31/2016 | C10: R2062861, | D10: 4631 HIGHLAWN DRIVE | E10: 4631 HIGHLAWN DRIVE | F10: Burnaby, BC V5C 3S9 | G10: 3888000 | H10: M. QUATRANO | V. HRELIA
A11: 03.23.25 | B11: 12/31/2023 | C11: R2814721, | D11: 4871 HIGHLAWN DRIVE | E11: 4871 HIGHLAWN DRIVE | F11: BURNABY BC V5C 3T2 | G11: 2288000 | H11: YANYING ZHOU | MEI PAN
A12: 03.23.25 | B12: 8/20/2024 | C12: R2914527, | D12: 4881 HIGHLAWN DRIVE | E12: 4881 HIGHLAWN DRIVE | F12: BURNABY BC V5C 3T2 | G12: 1950000 | H12: T.Lin | Y.Yang
A13: 03.23.25 | B13: 5/29/2022 | C13: R2637059, | D13: 4660 NORTHLAWN DRIVE | E13: 4660 NORTHLAWN DRIVE | F13: BURNABY BC V5C 3S1 | G13: 2188000 | H13: Shuming Wang | Weiwei Wang
A14: 03.23.25 | B14: 10/28/2021 | C14: R2512957, | D14: 4825 NORTHLAWN DRIVE | E14: 4825 NORTHLAWN DRIVE | F14: BURNABY BC V5C 3S2 | G14: 2800000 | H14: Trung Kiet Do
... A25: 03.23.25 | B25: 12/31/2023 | C25: R2800937, | D25: 4921 VENABLES STREET | E25: 4921 VENABLES STREET | F25: BURNABY BC V5B 1X8 | G25: 3988000 | H25: Home Owner
A29: ATTACHED
A30: 4.2.25 | B30: 12.26.24 | C30: R2899247, | D30: 309 4768 BRENTWOOD DRIVE | E30: 309 4768 BRENTWOOD DRIVE | F30: BURNABY BC V5C 0C7 | G30: 729900 | H30: CUI YAN MA | ZHUO WEN ZHOU | I30: T | J30: Y
A31: 4.2.25 | B31: 02.19.25 | C31: R2916804, | D31: 201 4788 BRENTWOOD DRIVE | E31: 201 4788 BRENTWOOD DRIVE | F31: BURNABY BC V5C 0C5 | G31: 729000 | H31: TRAN MY THI TRAN | I31: O | J31: Y
A32: 4.2.25 | B32: 02.12.25 | C32: R2849630, | D32: 2802 4400 BUCHANAN STREET | E32: 2802 4400 BUCHANAN STREET | F32: BURNABY BC V5C 0E3 | G32: 1880000 | H32: HO SUEN | MEI YUN QIAN | I32: T | J32: Y | K32: 3BR
A33: 4.2.25 | B33: 03.31.25 | C33: R2918409, | D33: 2003 4250 DAWSON STREET | E33: 2003 4250 DAWSON STREET | F33: BURNABY, BC V5C 4B1 | G33: 798000 | H33: SHAHRAM FASIHY | I33: O | J33: Y | M33: 04.02.25
A34: 4.2.25 | B34: 02.20.25 | C34: R2851939, | D34: 2802 2133 DOUGLAS ROAD | E34: 2802 2133 DOUGLAS ROAD | F34: BURNABY BC V5C 0E9 | G34: 938000 | H34: CHEN, JU | I34: T | J34: Y
A35: 4.2.25 | B35: 01.03.25 | C35: R2945361, | D35: 405 1728 GILMORE AVENUE | E35: 405 1728 GILMORE AVENUE | F35: BURNABY, BC V5C 0L3 | G35: 848800 | H35: PARMJIT SAGGU & VIKRAM SAGGU & JASBINDER PANESAR | I35: O | J35: Y | K35: CP
A36: 4.2.25 | B36: 12.31.24 | C36: R2912174, | D36: 1505 2186 GILMORE AVENUE | E36: 5339 MONARCH STREET | F36: BURNABY, BC V5G 1Z9 | G36: 1068000 | H36: KUN HO KU | I36: V | J36: Y
A37: 4.2.25 | B37: 12.31.24 | C37: R2914218, | D37: 2608 2186 GILMORE AVENUE | E37: 2608 2186 GILMORE AVENUE | F37: Burnaby, BC V5C 0N7 | G37: 1050000 | H37: Home Owner | I37: V | J37: N
A38: 4.2.25 | B38: 01.31.25 | C38: R2908605, | D38: 4507 2186 GILMORE AVENUE | E38: 2003 4250 DAWSON ST | F38: BURNABY, BC V5C 4B1 | G38: 1278000 | H38: SHAHRAM FASIHY | I38: O | J38: Y | K38: OTHER RESIDENCE LISTED 03.31.25 expiration | M38: 04.02.25
A39: 4.2.25 | B39: 01.31.25 | C39: R2908621, | D39: 4607 2186 GILMORE AVENUE | E39: 2003 4250 DAWSON ST | F39: BURNABY, BC V5C 4B1 | G39: 1288000 | H39: SHAHRAM FASIHY | I39: O | J39: Y | K39: OTHER RESIDENCE LISTED 03.31.25 expiration | M39: 04.02.25
A40: 4.2.25 | B40: 02.26.25 | C40: R2918659, | D40: 4709 2186 GILMORE AVENUE | E40: 701-8260 162A STREET | F40: SURREY, BC V4N 0P6 | G40: 899000 | H40: IZAK HALIGVA | I40: V | J40: Y
A41: 4.2.25 | B41: 12.31.24 | C41: R2898031, | D41: 2301 5311 GORING STREET | E41: 2301 5311 GORING STREET | F41: Burnaby, BC V5B 0B5 | G41: 1499900 | H41: MOHAMMAD ANSAR | I41: O | J41: Y
A42: 4.2.25 | B42: 03.01.25 | C42: R2944836, | D42: 1204 2225 HOLDOM AVENUE | E42: 1204 2225 HOLDOM AVENUE | F42: Burnaby, BC V5B 0A1 | G42: 879900 | H42: ALIREZA RABIEE | I42: V | J42: Y
A43: 4.2.25 | B43: 03.04.25 | C43: R2944216, | D43: 1308 4488 JUNEAU STREET | E43: 1308 4488 JUNEAU STREET | F43: Burnaby, BC V5C 0M4 | G43: 928000 | H43: PHILLIP ROY LUNDRIE | HUI XIN ZHONG | I43: O | J43: Y
A44: 4.2.25 | B44: 01.27.25 | C44: R2920074, | D44: 701 4488 JUNEAU STREET | E44: 701 4488 JUNEAU STREET | F44: BURNABY, BC V5C 0M4 | G44: 949900 | H44: CARMELA DE BENEDETTO | I44: V | J44: Y
A45: 4.2.25 | B45: 03.01.25 | C45: R2949136, | D45: 2107 4168 LOUGHEED HIGHWAY | E45: 201 1280 RICHARDS ST | F45: VANCOUVER, BC V6B 1S2 | G45: 990000 | H45: BRUC LEONARD HOBSON | VICTORIA CAROLINA OSORIO SANCHEZ | I45: V | J45: Y
A46: 4.2.25 | B46: 01.22.25 | C46: R2917054, | D46: 2409 4880 LOUGHEED HIGHWAY | E46: 3968 WEST 11th AVENUE | F46: VANCOUVER, BC V6R 2L2 | G46: 893000 | H46: XI YU GUO | I46: V | J46: Y
A47: 4.2.25 | B47: 12.31.24 | C47: R2866736, | D47: 3003 4880 LOUGHEED HIGHWAY | E47: 3003 4880 LOUGHEED HIGHWAY | F47: Burnaby, BC V5C 0N1 | G47: 988000 | H47: Home Owner | I47: V | J47: Y (developer)
A48: 4.2.25 | B48: 12.31.24 | C48: R2868864, | D48: 4102 4880 LOUGHEED HIGHWAY | E48: 4102 4880 LOUGHEED HIGHWAY | F48: Burnaby, BC V5C 0N1 | G48: 999000 | H48: Home Owner | I48: V | J48: N
A49: 4.2.25 | B49: 12.31.24 | C49: R2866541, | D49: 4202 4880 LOUGHEED HIGHWAY | E49: 4202 4880 LOUGHEED HIGHWAY | F49: Burnaby, BC V5C 0N1 | G49: 1048000 | H49: Home Owner | I49: V | J49: Y (developer)
A50: 4.2.25 | B50: 12.31.24 | C50: R2900969, | D50: 3302 4890 LOUGHEED HIGHWAY | E50: 3551 SHUSWAP AVENUE | F50: RICHMOND, BC V7E 2A9 | G50: 1008000 | H50: CHI KEUNG CHENG | I50: V | J50: Y
A51: 4.2.25 | B51: 12.31.24 | C51: R2875051, | D51: 3503 4890 LOUGHEED HIGHWAY | E51: 3503 - 4890 LOUGHEED HIGHWAY | F51: BURNABY, BC V5C 0N2 | G51: 1350000 | H51: YOU HUA HUANG | I51: V | J51: Y
... A58: 4.2.25 | B58: 12.31.24 | C58: R2899448, | D58: 4604 4485 SKYLINE DRIVE | E58: 4604 4485 SKYLINE DRIVE | F58: Burnaby, BC V5C 0J2 | G58: 1038000 | H58: JASON JAEHO LEE | I58: O | J58: Y
